Workbook

Sheet 工作表2
A1: 日期 | B1: 時間 | C1: 測試槽 | D1: 泵浦編號 | E1: 序號 | F1: 定子溫度 A | G1: 定子溫度 B | H1: 環境溫度 | I1: 運轉電流 (A) | J1: 泵浦 HP | K1: Alarm | L1: 1號水槽水溫度 | M1: 2號水槽水溫度
A2: 46077 | B2: 0.6875 | C2: 1號水槽 | D2: P-01 | E2: 202510001 | F2: 63.1 | G2: 62.6 | H2: 24 | I2: 6.13 | J2: =VLOOKUP(D2, [1]設備資料!$A:$E, 5, 0) -> 2 | K2: =IF(I2="", 0, IF(OR(I2=0, AND(J2=2, I2>6.6), AND(J2=3, I2>8.6), AND(J2=5, I2>14.1)), 1, 0)) -> 0 | L2: 33.6
A3: 46077 | B3: 0.6875 | C3: 1號水槽 | D3: P-02 | E3: 202510006 | F3: 58.4 | H3: 24 | I3: 6.03 | J3: =VLOOKUP(D3, [1]設備資料!$A:$E, 5, 0) -> 2 | K3: =IF(I3="", 0, IF(OR(I3=0, AND(J3=2, I3>6.6), AND(J3=3, I3>8.6), AND(J3=5, I3>14.1)), 1, 0)) -> 0 | L3: 33.6
A4: 46077 | B4: 0.6875 | C4: 1號水槽 | D4: P-05 | E4: 202511011 | F4: 68.7 | G4: 69.8 | H4: 24 | I4: 8.06 | J4: =VLOOKUP(D4, [1]設備資料!$A:$E, 5, 0) -> 3 | K4: =IF(I4="", 0, IF(OR(I4=0, AND(J4=2, I4>6.6), AND(J4=3, I4>8.6), AND(J4=5, I4>14.1)), 1, 0)) -> 0 | L4: 33.6
A5: 46077 | B5: 0.6875 | C5: 1號水槽 | D5: P-06 | E5: 202511012 | F5: 68.6 | H5: 24 | I5: 7.78 | J5: =VLOOKUP(D5, [1]設備資料!$A:$E, 5, 0) -> 3 | K5: =IF(I5="", 0, IF(OR(I5=0, AND(J5=2, I5>6.6), AND(J5=3, I5>8.6), AND(J5=5, I5>14.1)), 1, 0)) -> 0 | L5: 33.6
A6: 46077 | B6: 0.6875 | C6: 1號水槽 | D6: P-09 | E6: 202511001 | F6: 90.6 | G6: 91.5 | H6: 24 | I6: 13.62 | J6: =VLOOKUP(D6, [1]設備資料!$A:$E, 5, 0) -> 5 | K6: =IF(I6="", 0, IF(OR(I6=0, AND(J6=2, I6>6.6), AND(J6=3, I6>8.6), AND(J6=5, I6>14.1)), 1, 0)) -> 0 | L6: 33.6
A7: 46077 | B7: 0.6875 | C7: 1號水槽 | D7: P-10 | E7: 202511002 | F7: 86.8 | G7: 85.6 | H7: 24 | I7: 13.34 | J7: =VLOOKUP(D7, [1]設備資料!$A:$E, 5, 0) -> 5 | K7: =IF(I7="", 0, IF(OR(I7=0, AND(J7=2, I7>6.6), AND(J7=3, I7>8.6), AND(J7=5, I7>14.1)), 1, 0)) -> 0 | L7: 33.6
A8: 46077 | B8: 0.69444444 | C8: 2號水槽 | D8: P-03 | E8: 202510024 | F8: 62.5 | G8: 62.3 | H8: 24 | I8: 6.17 | J8: =VLOOKUP(D8, [1]設備資料!$A:$E, 5, 0) -> 2 | K8: =IF(I8="", 0, IF(OR(I8=0, AND(J8=2, I8>6.6), AND(J8=3, I8>8.6), AND(J8=5, I8>14.1)), 1, 0)) -> 0 | M8: 33.2
A9: 46077 | B9: 0.69444444 | C9: 2號水槽 | D9: P-04 | E9: 202510026 | F9: 65.8 | H9: 24 | I9: 6.47 | J9: =VLOOKUP(D9, [1]設備資料!$A:$E, 5, 0) -> 2 | K9: =IF(I9="", 0, IF(OR(I9=0, AND(J9=2, I9>6.6), AND(J9=3, I9>8.6), AND(J9=5, I9>14.1)), 1, 0)) -> 0 | M9: 33.2
A10: 46077 | B10: 0.69444444 | C10: 2號水槽 | D10: P-07 | E10: 202511017 | F10: 68.2 | G10: 68.5 | H10: 24 | I10: 7.85 | J10: =VLOOKUP(D10, [1]設備資料!$A:$E, 5, 0) -> 3 | K10: =IF(I10="", 0, IF(OR(I10=0, AND(J10=2, I10>6.6), AND(J10=3, I10>8.6), AND(J10=5, I10>14.1)), 1, 0)) -> 0 | M10: 33.2
A11: 46077 | B11: 0.69444444 | C11: 2號水槽 | D11: P-11 | E11: 202511005 | F11: 90.3 | G11: 89.4 | H11: 24 | I11: 13.35 | J11: =VLOOKUP(D11, [1]設備資料!$A:$E, 5, 0) -> 5 | K11: =IF(I11="", 0, IF(OR(I11=0, AND(J11=2, I11>6.6), AND(J11=3, I11>8.6), AND(J11=5, I11>14.1)), 1, 0)) -> 0 | M11: 33.2
A12: 46077 | B12: 0.69444444 | C12: 2號水槽 | D12: P-12 | E12: NA | F12: 90.4 | G12: 96.1 | H12: 24 | I12: 13.29 | J12: =VLOOKUP(D12, [1]設備資料!$A:$E, 5, 0) -> 5 | K12: =IF(I12="", 0, IF(OR(I12=0, AND(J12=2, I12>6.6), AND(J12=3, I12>8.6), AND(J12=5, I12>14.1)), 1, 0)) -> 0 | M12: 33.2
A13: 46078 | B13: 0.39583333 | C13: 1號水槽 | D13: P-01 | E13: 202510001 | F13: 75.1 | G13: 74.5 | H13: 25 | I13: 6.03 | J13: =VLOOKUP(D13, [1]設備資料!$A:$E, 5, 0) -> 2 | K13: =IF(I13="", 0, IF(OR(I13=0, AND(J13=2, I13>6.6), AND(J13=3, I13>8.6), AND(J13=5, I13>14.1)), 1, 0)) -> 0 | L13: 44.8
A14: 46078 | B14: 0.39583333 | C14: 1號水槽 | D14: P-02 | E14: 202510006 | F14: 71.2 | H14: 25 | I14: 5.78 | J14: =VLOOKUP(D14, [1]設備資料!$A:$E, 5, 0) -> 2 | K14: =IF(I14="", 0, IF(OR(I14=0, AND(J14=2, I14>6.6), AND(J14=3, I14>8.6), AND(J14=5, I14>14.1)), 1, 0)) -> 0 | L14: 44.8
A15: 46078 | B15: 0.39583333 | C15: 1號水槽 | D15: P-05 | E15: 202511011 | F15: 81.1 | G15: 81.9 | H15: 25 | I15: 7.86 | J15: =VLOOKUP(D15, [1]設備資料!$A:$E, 5, 0) -> 3 | K15: =IF(I15="", 0, IF(OR(I15=0, AND(J15=2, I15>6.6), AND(J15=3, I15>8.6), AND(J15=5, I15>14.1)), 1, 0)) -> 0 | L15: 44.8
A16: 46078 | B16: 0.39583333 | C16: 1號水槽 | D16: P-06 | E16: 202511012 | F16: 80.4 | H16: 25 | I16: 7.82 | J16: =VLOOKUP(D16, [1]設備資料!$A:$E, 5, 0) -> 3 | K16: =IF(I16="", 0, IF(OR(I16=0, AND(J16=2, I16>6.6), AND(J16=3, I16>8.6), AND(J16=5, I16>14.1)), 1, 0)) -> 0 | L16: 44.8
A17: 46078 | B17: 0.39583333 | C17: 1號水槽 | D17: P-09 | E17: 202511001 | F17: 102.1 | G17: 102.3 | H17: 25 | I17: 13.64 | J17: =VLOOKUP(D17, [1]設備資料!$A:$E, 5, 0) -> 5 | K17: =IF(I17="", 0, IF(OR(I17=0, AND(J17=2, I17>6.6), AND(J17=3, I17>8.6), AND(J17=5, I17>14.1)), 1, 0)) -> 0 | L17: 44.8
A18: 46078 | B18: 0.39583333 | C18: 1號水槽 | D18: P-10 | E18: 202511002 | F18: 98.2 | G18: 96.5 | H18: 25 | I18: 13.32 | J18: =VLOOKUP(D18, [1]設備資料!$A:$E, 5, 0) -> 5 | K18: =IF(I18="", 0, IF(OR(I18=0, AND(J18=2, I18>6.6), AND(J18=3, I18>8.6), AND(J18=5, I18>14.1)), 1, 0)) -> 0 | L18: 44.8
A19: 46078 | B19: 0.40277778 | C19: 2號水槽 | D19: P-03 | E19: 202510024 | F19: 74.5 | G19: 74.3 | H19: 25 | I19: 6.04 | J19: =VLOOKUP(D19, [1]設備資料!$A:$E, 5, 0) -> 2 | K19: =IF(I19="", 0, IF(OR(I19=0, AND(J19=2, I19>6.6), AND(J19=3, I19>8.6), AND(J19=5, I19>14.1)), 1, 0)) -> 0 | M19: 43.8
A20: 46078 | B20: 0.40277778 | C20: 2號水槽 | D20: P-04 | E20: 202510026 | F20: 77.8 | H20: 25 | I20: 6.08 | J20: =VLOOKUP(D20, [1]設備資料!$A:$E, 5, 0) -> 2 | K20: =IF(I20="", 0, IF(OR(I20=0, AND(J20=2, I20>6.6), AND(J20=3, I20>8.6), AND(J20=5, I20>14.1)), 1, 0)) -> 0 | M20: 43.8
A21: 46078 | B21: 0.40277778 | C21: 2號水槽 | D21: P-07 | E21: 202511017 | F21: 80.2 | G21: 80.9 | H21: 25 | I21: 7.55 | J21: =VLOOKUP(D21, [1]設備資料!$A:$E, 5, 0) -> 3 | K21: =IF(I21="", 0, IF(OR(I21=0, AND(J21=2, I21>6.6), AND(J21=3, I21>8.6), AND(J21=5, I21>14.1)), 1, 0)) -> 0 | M21: 43.8
A22: 46078 | B22: 0.40277778 | C22: 2號水槽 | D22: P-11 | E22: 202511005 | F22: 102.3 | G22: 101.4 | H22: 25 | I22: 13.31 | J22: =VLOOKUP(D22, [1]設備資料!$A:$E, 5, 0) -> 5 | K22: =IF(I22="", 0, IF(OR(I22=0, AND(J22=2, I22>6.6), AND(J22=3, I22>8.6), AND(J22=5, I22>14.1)), 1, 0)) -> 0 | M22: 43.8
A23: 46078 | B23: 0.40277778 | C23: 2號水槽 | D23: P-12 | E23: NA | F23: 102.4 | G23: 97.2 | H23: 25 | I23: 13.23 | J23: =VLOOKUP(D23, [1]設備資料!$A:$E, 5, 0) -> 5 | K23: =IF(I23="", 0, IF(OR(I23=0, AND(J23=2, I23>6.6), AND(J23=3, I23>8.6), AND(J23=5, I23>14.1)), 1, 0)) -> 0 | M23: 43.8
A24: 46078 | B24: 0.6875 | C24: 1號水槽 | D24: P-01 | E24: 202510001 | F24: 75.6 | G24: 74.9 | H24: 27 | J24: =VLOOKUP(D24, [1]設備資料!$A:$E, 5, 0) -> 2 | K24: =IF(I24="", 0, IF(OR(I24=0, AND(J24=2, I24>6.6), AND(J24=3, I24>8.6), AND(J24=5, I24>14.1)), 1, 0)) -> 0 | L24: 45.1
A25: 46078 | B25: 0.6875 | C25: 1號水槽 | D25: P-02 | E25: 202510006 | F25: 71.4 | H25: 27 | J25: =VLOOKUP(D25, [1]設備資料!$A:$E, 5, 0) -> 2 | K25: =IF(I25="", 0, IF(OR(I25=0, AND(J25=2, I25>6.6), AND(J25=3, I25>8.6), AND(J25=5, I25>14.1)), 1, 0)) -> 0 | L25: 45.1
A26: 46078 | B26: 0.6875 | C26: 1號水槽 | D26: P-05 | E26: 202511011 | F26: 81.2 | G26: 82.5 | H26: 27 | J26: =VLOOKUP(D26, [1]設備資料!$A:$E, 5, 0) -> 3 | K26: =IF(I26="", 0, IF(OR(I26=0, AND(J26=2, I26>6.6), AND(J26=3, I26>8.6), AND(J26=5, I26>14.1)), 1, 0)) -> 0 | L26: 45.1
A27: 46078 | B27: 0.6875 | C27: 1號水槽 | D27: P-06 | E27: 202511012 | F27: 80.9 | H27: 27 | J27: =VLOOKUP(D27, [1]設備資料!$A:$E, 5, 0) -> 3 | K27: =IF(I27="", 0, IF(OR(I27=0, AND(J27=2, I27>6.6), AND(J27=3, I27>8.6), AND(J27=5, I27>14.1)), 1, 0)) -> 0 | L27: 45.1
A28: 46078 | B28: 0.6875 | C28: 1號水槽 | D28: P-09 | E28: 202511001 | F28: 103.1 | G28: 101.8 | H28: 27 | J28: =VLOOKUP(D28, [1]設備資料!$A:$E, 5, 0) -> 5 | K28: =IF(I28="", 0, IF(OR(I28=0, AND(J28=2, I28>6.6), AND(J28=3, I28>8.6), AND(J28=5, I28>14.1)), 1, 0)) -> 0 | L28: 45.1
A29: 46078 | B29: 0.6875 | C29: 1號水槽 | D29: P-10 | E29: 202511002 | F29: 98 | G29: 97.2 | H29: 27 | J29: =VLOOKUP(D29, [1]設備資料!$A:$E, 5, 0) -> 5 | K29: =IF(I29="", 0, IF(OR(I29=0, AND(J29=2, I29>6.6), AND(J29=3, I29>8.6), AND(J29=5, I29>14.1)), 1, 0)) -> 0 | L29: 45.1
A30: 46078 | B30: 0.69444444 | C30: 2號水槽 | D30: P-03 | E30: 202510024 | F30: 74.7 | G30: 74.7 | H30: 27 | J30: =VLOOKUP(D30, [1]設備資料!$A:$E, 5, 0) -> 2 | K30: =IF(I30="", 0, IF(OR(I30=0, AND(J30=2, I30>6.6), AND(J30=3, I30>8.6), AND(J30=5, I30>14.1)), 1, 0)) -> 0 | M30: 44.2
A31: 46078 | B31: 0.69444444 | C31: 2號水槽 | D31: P-04 | E31: 202510026 | F31: 78 | H31: 27 | J31: =VLOOKUP(D31, [1]設備資料!$A:$E, 5, 0) -> 2 | K31: =IF(I31="", 0, IF(OR(I31=0, AND(J31=2, I31>6.6), AND(J31=3, I31>8.6), AND(J31=5, I31>14.1)), 1, 0)) -> 0 | M31: 44.2
A32: 46078 | B32: 0.69444444 | C32: 2號水槽 | D32: P-07 | E32: 202511017 | F32: 81.2 | G32: 81 | H32: 27 | J32: =VLOOKUP(D32, [1]設備資料!$A:$E, 5, 0) -> 3 | K32: =IF(I32="", 0, IF(OR(I32=0, AND(J32=2, I32>6.6), AND(J32=3, I32>8.6), AND(J32=5, I32>14.1)), 1, 0)) -> 0 | M32: 44.2
A33: 46078 | B33: 0.69444444 | C33: 2號水槽 | D33: P-11 | E33: 202511005 | F33: 101.7 | G33: 97 | H33: 27 | J33: =VLOOKUP(D33, [1]設備資料!$A:$E, 5, 0) -> 5 | K33: =IF(I33="", 0, IF(OR(I33=0, AND(J33=2, I33>6.6), AND(J33=3, I33>8.6), AND(J33=5, I33>14.1)), 1, 0)) -> 0 | M33: 44.2
A34: 46078 | B34: 0.69444444 | C34: 2號水槽 | D34: P-12 | E34: NA | F34: 103.7 | G34: 97.5 | H34: 27 | J34: =VLOOKUP(D34, [1]設備資料!$A:$E, 5, 0) -> 5 | K34: =IF(I34="", 0, IF(OR(I34=0, AND(J34=2, I34>6.6), AND(J34=3, I34>8.6), AND(J34=5, I34>14.1)), 1, 0)) -> 0 | M34: 44.2
A35: 46079 | B35: 0.39583333 | C35: 1號水槽 | D35: P-01 | E35: 202510001 | F35: 78 | G35: 77.4 | H35: 23 | I35: 6.12 | J35: =VLOOKUP(D35, [1]設備資料!$A:$E, 5, 0) -> 2 | K35: =IF(I35="", 0, IF(OR(I35=0, AND(J35=2, I35>6.6), AND(J35=3, I35>8.6), AND(J35=5, I35>14.1)), 1, 0)) -> 0 | L35: 47.2
A36: 46079 | B36: 0.39583333 | C36: 1號水槽 | D36: P-02 | E36: 202510006 | F36: 73.6 | H36: 23 | I36: 5.98 | J36: =VLOOKUP(D36, [1]設備資料!$A:$E, 5, 0) -> 2 | K36: =IF(I36="", 0, IF(OR(I36=0, AND(J36=2, I36>6.6), AND(J36=3, I36>8.6), AND(J36=5, I36>14.1)), 1, 0)) -> 0 | L36: 47.2
A37: 46079 | B37: 0.39583333 | C37: 1號水槽 | D37: P-05 | E37: 202511011 | F37: 85 | G37: 84 | H37: 23 | I37: 7.89 | J37: =VLOOKUP(D37, [1]設備資料!$A:$E, 5, 0) -> 3 | K37: =IF(I37="", 0, IF(OR(I37=0, AND(J37=2, I37>6.6), AND(J37=3, I37>8.6), AND(J37=5, I37>14.1)), 1, 0)) -> 0 | L37: 47.2
A38: 46079 | B38: 0.39583333 | C38: 1號水槽 | D38: P-06 | E38: 202511012 | F38: 83.5 | H38: 23 | I38: 7.92 | J38: =VLOOKUP(D38, [1]設備資料!$A:$E, 5, 0) -> 3 | K38: =IF(I38="", 0, IF(OR(I38=0, AND(J38=2, I38>6.6), AND(J38=3, I38>8.6), AND(J38=5, I38>14.1)), 1, 0)) -> 0 | L38: 47.2
A39: 46079 | B39: 0.39583333 | C39: 1號水槽 | D39: P-09 | E39: 202511001 | F39: 105.7 | G39: 104.7 | H39: 23 | I39: 13.75 | J39: =VLOOKUP(D39, [1]設備資料!$A:$E, 5, 0) -> 5 | K39: =IF(I39="", 0, IF(OR(I39=0, AND(J39=2, I39>6.6), AND(J39=3, I39>8.6), AND(J39=5, I39>14.1)), 1, 0)) -> 0 | L39: 47.2
A40: 46079 | B40: 0.39583333 | C40: 1號水槽 | D40: P-10 | E40: 202511002 | F40: 100.7 | G40: 99.8 | H40: 23 | I40: 13.45 | J40: =VLOOKUP(D40, [1]設備資料!$A:$E, 5, 0) -> 5 | K40: =IF(I40="", 0, IF(OR(I40=0, AND(J40=2, I40>6.6), AND(J40=3, I40>8.6), AND(J40=5, I40>14.1)), 1, 0)) -> 0 | L40: 47.2
...
