Workbook

Sheet 監測總表
A1: 日期 | B1: 時間 | C1: 測試槽 | D1: 泵浦編號 | E1: 序號 | F1: 定子溫度 A | G1: 定子溫度 B | H1: 環境溫度 | I1: 運轉電流 (A) | J1: 泵浦 HP | K1: Alarm | L1: 1號水槽水溫度 | M1: 2號水槽水溫度 | N1: 運行狀態 | O1: 備註
A2: 46057 | B2: 0.44444444 | C2: 2號水槽 | D2: P-03 | E2: 202510024 | F2: 18 | G2: 18.1 | H2: 22 | J2: =VLOOKUP(D2, [1]設備資料!$A:$E, 5, 0) -> 2 | K2: =IF(I2="", 0, IF(OR(I2=0, AND(J2=2, I2>6.6), AND(J2=3, I2>8.6), AND(J2=5, I2>14.1)), 1, 0)) -> 0 | M2: 18.2 | N2: 待機 | O2: 測試開始前
A3: 46057 | B3: 0.44444444 | C3: 2號水槽 | D3: P-04 | E3: 202510026 | F3: 18.1 | G3: -- | H3: 22 | J3: =VLOOKUP(D3, [1]設備資料!$A:$E, 5, 0) -> 2 | K3: =IF(I3="", 0, IF(OR(I3=0, AND(J3=2, I3>6.6), AND(J3=3, I3>8.6), AND(J3=5, I3>14.1)), 1, 0)) -> 0 | M3: 18.2 | N3: 待機 | O3: 測試開始前
A4: 46057 | B4: 0.44444444 | C4: 2號水槽 | D4: P-07 | E4: 202511017 | F4: 18.1 | G4: 18.2 | H4: 22 | J4: =VLOOKUP(D4, [1]設備資料!$A:$E, 5, 0) -> 3 | K4: =IF(I4="", 0, IF(OR(I4=0, AND(J4=2, I4>6.6), AND(J4=3, I4>8.6), AND(J4=5, I4>14.1)), 1, 0)) -> 0 | M4: 18.2 | N4: 待機 | O4: 測試開始前
A5: 46057 | B5: 0.44444444 | C5: 2號水槽 | D5: P-11 | E5: 202511005 | F5: 18.3 | G5: 18.3 | H5: 22 | J5: =VLOOKUP(D5, [1]設備資料!$A:$E, 5, 0) -> 5 | K5: =IF(I5="", 0, IF(OR(I5=0, AND(J5=2, I5>6.6), AND(J5=3, I5>8.6), AND(J5=5, I5>14.1)), 1, 0)) -> 0 | M5: 18.2 | N5: 待機 | O5: 測試開始前
A6: 46057 | B6: 0.44444444 | C6: 2號水槽 | D6: P-12 | E6: NA | F6: 18.3 | G6: 18.3 | H6: 22 | J6: =VLOOKUP(D6, [1]設備資料!$A:$E, 5, 0) -> 5 | K6: =IF(I6="", 0, IF(OR(I6=0, AND(J6=2, I6>6.6), AND(J6=3, I6>8.6), AND(J6=5, I6>14.1)), 1, 0)) -> 0 | M6: 18.2 | N6: 待機 | O6: 測試開始前
A7: 46057 | B7: 0.44444444 | C7: 2號水槽 | D7: P-03 | E7: 202510024 | F7: 39.5 | G7: 40 | H7: 22 | I7: 6.61 | J7: =VLOOKUP(D7, [1]設備資料!$A:$E, 5, 0) -> 2 | K7: =IF(I7="", 0, IF(OR(I7=0, AND(J7=2, I7>6.6), AND(J7=3, I7>8.6), AND(J7=5, I7>14.1)), 1, 0)) -> 1 | M7: 18.4 | N7: 啟動中 | O7: 安裝首日-第0時-啟動電流: 14.1A
A8: 46057 | B8: 0.44513889 | C8: 2號水槽 | D8: P-04 | E8: 202510026 | F8: 43.1 | G8: -- | H8: 22 | I8: 6.59 | J8: =VLOOKUP(D8, [1]設備資料!$A:$E, 5, 0) -> 2 | K8: =IF(I8="", 0, IF(OR(I8=0, AND(J8=2, I8>6.6), AND(J8=3, I8>8.6), AND(J8=5, I8>14.1)), 1, 0)) -> 0 | M8: 18.4 | N8: 啟動中 | O8: 安裝首日-第0時-啟動電流: 11.7A
A9: 46057 | B9: 0.44583333 | C9: 2號水槽 | D9: P-07 | E9: 202511017 | F9: 38.3 | G9: 38.3 | H9: 22 | I9: 8.16 | J9: =VLOOKUP(D9, [1]設備資料!$A:$E, 5, 0) -> 3 | K9: =IF(I9="", 0, IF(OR(I9=0, AND(J9=2, I9>6.6), AND(J9=3, I9>8.6), AND(J9=5, I9>14.1)), 1, 0)) -> 0 | M9: 18.4 | N9: 啟動中 | O9: 安裝首日-第0時-啟動電流: 10.1A
A10: 46057 | B10: 0.44722222 | C10: 2號水槽 | D10: P-11 | E10: 202511005 | F10: 38.4 | G10: 36.2 | H10: 22 | I10: 13.39 | J10: =VLOOKUP(D10, [1]設備資料!$A:$E, 5, 0) -> 5 | K10: =IF(I10="", 0, IF(OR(I10=0, AND(J10=2, I10>6.6), AND(J10=3, I10>8.6), AND(J10=5, I10>14.1)), 1, 0)) -> 0 | M10: 18.4 | N10: 啟動中 | O10: 安裝首日-第0時-啟動電流: 14.4A
A11: 46057 | B11: 0.44791667 | C11: 2號水槽 | D11: P-12 | E11: NA | F11: 32.3 | G11: 31.4 | H11: 22 | I11: 14.1 | J11: =VLOOKUP(D11, [1]設備資料!$A:$E, 5, 0) -> 5 | K11: =IF(I11="", 0, IF(OR(I11=0, AND(J11=2, I11>6.6), AND(J11=3, I11>8.6), AND(J11=5, I11>14.1)), 1, 0)) -> 0 | M11: 18.4 | N11: 啟動中 | O11: 安裝首日-第0時-啟動電流: 26.2A
A12: 46057 | B12: 0.45833333 | C12: 1號水槽 | D12: P-01 | E12: 202510001 | F12: 51.5 | G12: 51.7 | H12: 26 | I12: 6.43 | J12: =VLOOKUP(D12, [1]設備資料!$A:$E, 5, 0) -> 2 | K12: =IF(I12="", 0, IF(OR(I12=0, AND(J12=2, I12>6.6), AND(J12=3, I12>8.6), AND(J12=5, I12>14.1)), 1, 0)) -> 0 | L12: 27.3 | N12: 正常 | O12: 安裝首日-第2時
A13: 46057 | B13: 0.45902778 | C13: 1號水槽 | D13: P-02 | E13: 202510006 | F13: 48 | G13: -- | H13: 26 | I13: 6.54 | J13: =VLOOKUP(D13, [1]設備資料!$A:$E, 5, 0) -> 2 | K13: =IF(I13="", 0, IF(OR(I13=0, AND(J13=2, I13>6.6), AND(J13=3, I13>8.6), AND(J13=5, I13>14.1)), 1, 0)) -> 0 | L13: 27.3 | N13: 正常 | O13: 安裝首日-第2時
A14: 46057 | B14: 0.45972222 | C14: 1號水槽 | D14: P-05 | E14: 202511011 | F14: 56.4 | G14: 57.1 | H14: 26 | I14: 7.89 | J14: =VLOOKUP(D14, [1]設備資料!$A:$E, 5, 0) -> 3 | K14: =IF(I14="", 0, IF(OR(I14=0, AND(J14=2, I14>6.6), AND(J14=3, I14>8.6), AND(J14=5, I14>14.1)), 1, 0)) -> 0 | L14: 27.3 | N14: 正常 | O14: 安裝首日-第2時
A15: 46057 | B15: 0.46041667 | C15: 1號水槽 | D15: P-06 | E15: 202511012 | F15: 57.1 | G15: -- | H15: 26 | I15: 7.85 | J15: =VLOOKUP(D15, [1]設備資料!$A:$E, 5, 0) -> 3 | K15: =IF(I15="", 0, IF(OR(I15=0, AND(J15=2, I15>6.6), AND(J15=3, I15>8.6), AND(J15=5, I15>14.1)), 1, 0)) -> 0 | L15: 27.3 | N15: 正常 | O15: 安裝首日-第2時
A16: 46057 | B16: 0.46111111 | C16: 1號水槽 | D16: P-09 | E16: 202511001 | F16: 72 | G16: 73.1 | H16: 26 | I16: 13.35 | J16: =VLOOKUP(D16, [1]設備資料!$A:$E, 5, 0) -> 5 | K16: =IF(I16="", 0, IF(OR(I16=0, AND(J16=2, I16>6.6), AND(J16=3, I16>8.6), AND(J16=5, I16>14.1)), 1, 0)) -> 0 | L16: 27.3 | N16: 正常 | O16: 安裝首日-第2時
A17: 46057 | B17: 0.46180556 | C17: 1號水槽 | D17: P-10 | E17: 202511002 | F17: 72.2 | G17: 71.2 | H17: 26 | I17: 13.15 | J17: =VLOOKUP(D17, [1]設備資料!$A:$E, 5, 0) -> 5 | K17: =IF(I17="", 0, IF(OR(I17=0, AND(J17=2, I17>6.6), AND(J17=3, I17>8.6), AND(J17=5, I17>14.1)), 1, 0)) -> 0 | L17: 27.3 | N17: 正常 | O17: 安裝首日-第2時
A18: 46057 | B18: 0.48611111 | C18: 2號水槽 | D18: P-03 | E18: 202510024 | F18: 51.3 | G18: 51.2 | H18: 26 | I18: 6.28 | J18: =VLOOKUP(D18, [1]設備資料!$A:$E, 5, 0) -> 2 | K18: =IF(I18="", 0, IF(OR(I18=0, AND(J18=2, I18>6.6), AND(J18=3, I18>8.6), AND(J18=5, I18>14.1)), 1, 0)) -> 0 | M18: 26 | N18: 運行中 | O18: 安裝首日-第1時
A19: 46057 | B19: 0.48680556 | C19: 2號水槽 | D19: P-04 | E19: 202510026 | F19: 54.5 | G19: -- | H19: 26 | I19: 6.32 | J19: =VLOOKUP(D19, [1]設備資料!$A:$E, 5, 0) -> 2 | K19: =IF(I19="", 0, IF(OR(I19=0, AND(J19=2, I19>6.6), AND(J19=3, I19>8.6), AND(J19=5, I19>14.1)), 1, 0)) -> 0 | M19: 26 | N19: 運行中 | O19: 安裝首日-第1時
A20: 46057 | B20: 0.4875 | C20: 2號水槽 | D20: P-07 | E20: 202511017 | F20: 57.1 | G20: 57.8 | H20: 26 | I20: 7.76 | J20: =VLOOKUP(D20, [1]設備資料!$A:$E, 5, 0) -> 3 | K20: =IF(I20="", 0, IF(OR(I20=0, AND(J20=2, I20>6.6), AND(J20=3, I20>8.6), AND(J20=5, I20>14.1)), 1, 0)) -> 0 | M20: 26 | N20: 運行中 | O20: 安裝首日-第1時
A21: 46057 | B21: 0.48888889 | C21: 2號水槽 | D21: P-11 | E21: 202511005 | F21: 72.4 | G21: 68.6 | H21: 26 | I21: 13.05 | J21: =VLOOKUP(D21, [1]設備資料!$A:$E, 5, 0) -> 5 | K21: =IF(I21="", 0, IF(OR(I21=0, AND(J21=2, I21>6.6), AND(J21=3, I21>8.6), AND(J21=5, I21>14.1)), 1, 0)) -> 0 | M21: 26 | N21: 運行中 | O21: 安裝首日-第1時
A22: 46057 | B22: 0.48958333 | C22: 2號水槽 | D22: P-12 | E22: NA | F22: 74.2 | G22: 70 | H22: 26 | I22: 13.57 | J22: =VLOOKUP(D22, [1]設備資料!$A:$E, 5, 0) -> 5 | K22: =IF(I22="", 0, IF(OR(I22=0, AND(J22=2, I22>6.6), AND(J22=3, I22>8.6), AND(J22=5, I22>14.1)), 1, 0)) -> 0 | M22: 26 | N22: 運行中 | O22: 安裝首日-第1時
A23: 46057 | B23: 0.5 | C23: 1號水槽 | D23: P-01 | E23: 202510001 | F23: 55.3 | G23: 55.2 | H23: 26 | I23: 6.42 | J23: =VLOOKUP(D23, [1]設備資料!$A:$E, 5, 0) -> 2 | K23: =IF(I23="", 0, IF(OR(I23=0, AND(J23=2, I23>6.6), AND(J23=3, I23>8.6), AND(J23=5, I23>14.1)), 1, 0)) -> 0 | L23: 29.2 | N23: 正常 | O23: 安裝首日-第3時
A24: 46057 | B24: 0.50069444 | C24: 1號水槽 | D24: P-02 | E24: 202510006 | F24: 51.3 | G24: -- | H24: 26 | I24: 6.63 | J24: =VLOOKUP(D24, [1]設備資料!$A:$E, 5, 0) -> 2 | K24: =IF(I24="", 0, IF(OR(I24=0, AND(J24=2, I24>6.6), AND(J24=3, I24>8.6), AND(J24=5, I24>14.1)), 1, 0)) -> 1 | L24: 29.2 | N24: 正常 | O24: 安裝首日-第3時
A25: 46057 | B25: 0.50138889 | C25: 1號水槽 | D25: P-05 | E25: 202511011 | F25: 60.3 | G25: 61.1 | H25: 26 | I25: 7.72 | J25: =VLOOKUP(D25, [1]設備資料!$A:$E, 5, 0) -> 3 | K25: =IF(I25="", 0, IF(OR(I25=0, AND(J25=2, I25>6.6), AND(J25=3, I25>8.6), AND(J25=5, I25>14.1)), 1, 0)) -> 0 | L25: 29.2 | N25: 正常 | O25: 安裝首日-第3時
A26: 46057 | B26: 0.50208333 | C26: 1號水槽 | D26: P-06 | E26: 202511012 | F26: 60.4 | G26: -- | H26: 26 | I26: 7.73 | J26: =VLOOKUP(D26, [1]設備資料!$A:$E, 5, 0) -> 3 | K26: =IF(I26="", 0, IF(OR(I26=0, AND(J26=2, I26>6.6), AND(J26=3, I26>8.6), AND(J26=5, I26>14.1)), 1, 0)) -> 0 | L26: 29.2 | N26: 正常 | O26: 安裝首日-第3時
A27: 46057 | B27: 0.50277778 | C27: 1號水槽 | D27: P-09 | E27: 202511001 | F27: 75.5 | G27: 76.5 | H27: 26 | I27: 13.16 | J27: =VLOOKUP(D27, [1]設備資料!$A:$E, 5, 0) -> 5 | K27: =IF(I27="", 0, IF(OR(I27=0, AND(J27=2, I27>6.6), AND(J27=3, I27>8.6), AND(J27=5, I27>14.1)), 1, 0)) -> 0 | L27: 29.2 | N27: 正常 | O27: 安裝首日-第3時
A28: 46057 | B28: 0.50347222 | C28: 1號水槽 | D28: P-10 | E28: 202511002 | F28: 75.3 | G28: 74.2 | H28: 26 | I28: 13.79 | J28: =VLOOKUP(D28, [1]設備資料!$A:$E, 5, 0) -> 5 | K28: =IF(I28="", 0, IF(OR(I28=0, AND(J28=2, I28>6.6), AND(J28=3, I28>8.6), AND(J28=5, I28>14.1)), 1, 0)) -> 0 | L28: 29.2 | N28: 正常 | O28: 安裝首日-第3時
A29: 46057 | B29: 0.52777778 | C29: 2號水槽 | D29: P-03 | E29: 202510024 | F29: 54.6 | G29: 54.7 | H29: 26 | I29: 6.41 | J29: =VLOOKUP(D29, [1]設備資料!$A:$E, 5, 0) -> 2 | K29: =IF(I29="", 0, IF(OR(I29=0, AND(J29=2, I29>6.6), AND(J29=3, I29>8.6), AND(J29=5, I29>14.1)), 1, 0)) -> 0 | M29: 27.8 | N29: 正常 | O29: 安裝首日-第3時
A30: 46057 | B30: 0.52847222 | C30: 2號水槽 | D30: P-04 | E30: 202510026 | F30: 59.9 | G30: -- | H30: 26 | I30: 6.2 | J30: =VLOOKUP(D30, [1]設備資料!$A:$E, 5, 0) -> 2 | K30: =IF(I30="", 0, IF(OR(I30=0, AND(J30=2, I30>6.6), AND(J30=3, I30>8.6), AND(J30=5, I30>14.1)), 1, 0)) -> 0 | M30: 27.8 | N30: 正常 | O30: 安裝首日-第3時
A31: 46057 | B31: 0.52916667 | C31: 2號水槽 | D31: P-07 | E31: 202511017 | F31: 61.4 | G31: 61.8 | H31: 26 | I31: 7.77 | J31: =VLOOKUP(D31, [1]設備資料!$A:$E, 5, 0) -> 3 | K31: =IF(I31="", 0, IF(OR(I31=0, AND(J31=2, I31>6.6), AND(J31=3, I31>8.6), AND(J31=5, I31>14.1)), 1, 0)) -> 0 | M31: 27.8 | N31: 正常 | O31: 安裝首日-第3時
A32: 46057 | B32: 0.53055556 | C32: 2號水槽 | D32: P-11 | E32: 202511005 | F32: 76.4 | G32: 72 | H32: 26 | I32: 13.32 | J32: =VLOOKUP(D32, [1]設備資料!$A:$E, 5, 0) -> 5 | K32: =IF(I32="", 0, IF(OR(I32=0, AND(J32=2, I32>6.6), AND(J32=3, I32>8.6), AND(J32=5, I32>14.1)), 1, 0)) -> 0 | M32: 27.8 | N32: 正常 | O32: 安裝首日-第3時
A33: 46057 | B33: 0.53125 | C33: 2號水槽 | D33: P-12 | E33: NA | F33: 77 | G33: 72.4 | H33: 26 | I33: 13.16 | J33: =VLOOKUP(D33, [1]設備資料!$A:$E, 5, 0) -> 5 | K33: =IF(I33="", 0, IF(OR(I33=0, AND(J33=2, I33>6.6), AND(J33=3, I33>8.6), AND(J33=5, I33>14.1)), 1, 0)) -> 0 | M33: 27.8 | N33: 正常 | O33: 安裝首日-第3時
A34: 46057 | B34: 0.58333333 | C34: 1號水槽 | D34: P-01 | E34: 202510001 | F34: 56.8 | G34: 56.9 | H34: 28 | J34: =VLOOKUP(D34, [1]設備資料!$A:$E, 5, 0) -> 2 | K34: =IF(I34="", 0, IF(OR(I34=0, AND(J34=2, I34>6.6), AND(J34=3, I34>8.6), AND(J34=5, I34>14.1)), 1, 0)) -> 0 | L34: 27.3 | N34: 正常 | O34: 安裝首日-第5時
A35: 46057 | B35: 0.58333333 | C35: 1號水槽 | D35: P-02 | E35: 202510006 | F35: 53 | G35: -- | H35: 28 | J35: =VLOOKUP(D35, [1]設備資料!$A:$E, 5, 0) -> 2 | K35: =IF(I35="", 0, IF(OR(I35=0, AND(J35=2, I35>6.6), AND(J35=3, I35>8.6), AND(J35=5, I35>14.1)), 1, 0)) -> 0 | L35: 27.3 | N35: 正常 | O35: 安裝首日-第5時
A36: 46057 | B36: 0.58333333 | C36: 1號水槽 | D36: P-05 | E36: 202511011 | F36: 62.3 | G36: 63.2 | H36: 28 | J36: =VLOOKUP(D36, [1]設備資料!$A:$E, 5, 0) -> 3 | K36: =IF(I36="", 0, IF(OR(I36=0, AND(J36=2, I36>6.6), AND(J36=3, I36>8.6), AND(J36=5, I36>14.1)), 1, 0)) -> 0 | L36: 27.3 | N36: 正常 | O36: 安裝首日-第5時
A37: 46057 | B37: 0.58333333 | C37: 1號水槽 | D37: P-06 | E37: 202511012 | F37: 62.6 | G37: -- | H37: 28 | J37: =VLOOKUP(D37, [1]設備資料!$A:$E, 5, 0) -> 3 | K37: =IF(I37="", 0, IF(OR(I37=0, AND(J37=2, I37>6.6), AND(J37=3, I37>8.6), AND(J37=5, I37>14.1)), 1, 0)) -> 0 | L37: 27.3 | N37: 正常 | O37: 安裝首日-第5時
A38: 46057 | B38: 0.58333333 | C38: 1號水槽 | D38: P-09 | E38: 202511001 | F38: 77.4 | G38: 78.8 | H38: 28 | J38: =VLOOKUP(D38, [1]設備資料!$A:$E, 5, 0) -> 5 | K38: =IF(I38="", 0, IF(OR(I38=0, AND(J38=2, I38>6.6), AND(J38=3, I38>8.6), AND(J38=5, I38>14.1)), 1, 0)) -> 0 | L38: 27.3 | N38: 正常 | O38: 安裝首日-第5時
A39: 46057 | B39: 0.58333333 | C39: 1號水槽 | D39: P-10 | E39: 202511002 | F39: 77.5 | G39: 76.8 | H39: 28 | J39: =VLOOKUP(D39, [1]設備資料!$A:$E, 5, 0) -> 5 | K39: =IF(I39="", 0, IF(OR(I39=0, AND(J39=2, I39>6.6), AND(J39=3, I39>8.6), AND(J39=5, I39>14.1)), 1, 0)) -> 0 | L39: 27.3 | N39: 正常 | O39: 安裝首日-第5時
A40: 46057 | B40: 0.61111111 | C40: 2號水槽 | D40: P-03 | E40: 202510024 | F40: 56.2 | G40: 56.2 | H40: 28 | J40: =VLOOKUP(D40, [1]設備資料!$A:$E, 5, 0) -> 2 | K40: =IF(I40="", 0, IF(OR(I40=0, AND(J40=2, I40>6.6), AND(J40=3, I40>8.6), AND(J40=5, I40>14.1)), 1, 0)) -> 0 | M40: 26 | N40: 正常 | O40: 安裝首日-第4時
...

Sheet 工作表2
A1: 日期 | B1: 時間 | C1: 測試槽 | D1: 泵浦編號 | E1: 序號 | F1: 定子溫度 A | G1: 定子溫度 B | H1: 環境溫度 | I1: 運轉電流 (A) | J1: 泵浦 HP | K1: Alarm | L1: 1號水槽水溫度 | M1: 2號水槽水溫度
A2: 46077 | B2: 0.39583333 | C2: 1號水槽 | D2: P-01 | E2: 202510001 | F2: 21.2 | G2: 21.2 | H2: 23 | I2: 6.56 | J2: =VLOOKUP(D2, [1]設備資料!$A:$E, 5, 0) -> 2 | K2: =IF(I2="", 0, IF(OR(I2=0, AND(J2=2, I2>6.6), AND(J2=3, I2>8.6), AND(J2=5, I2>14.1)), 1, 0)) -> 0 | L2: 21.2
A3: 46077 | B3: 0.39583333 | C3: 1號水槽 | D3: P-02 | E3: 202510006 | F3: 21.2 | H3: 23 | I3: 6.53 | J3: =VLOOKUP(D3, [1]設備資料!$A:$E, 5, 0) -> 2 | K3: =IF(I3="", 0, IF(OR(I3=0, AND(J3=2, I3>6.6), AND(J3=3, I3>8.6), AND(J3=5, I3>14.1)), 1, 0)) -> 0 | L3: 21.2
A4: 46077 | B4: 0.39583333 | C4: 1號水槽 | D4: P-05 | E4: 202511011 | F4: 21.2 | G4: 21.2 | H4: 23 | I4: 8.36 | J4: =VLOOKUP(D4, [1]設備資料!$A:$E, 5, 0) -> 3 | K4: =IF(I4="", 0, IF(OR(I4=0, AND(J4=2, I4>6.6), AND(J4=3, I4>8.6), AND(J4=5, I4>14.1)), 1, 0)) -> 0 | L4: 21.2
A5: 46077 | B5: 0.39583333 | C5: 1號水槽 | D5: P-06 | E5: 202511012 | F5: 21.2 | H5: 23 | I5: 8.47 | J5: =VLOOKUP(D5, [1]設備資料!$A:$E, 5, 0) -> 3 | K5: =IF(I5="", 0, IF(OR(I5=0, AND(J5=2, I5>6.6), AND(J5=3, I5>8.6), AND(J5=5, I5>14.1)), 1, 0)) -> 0 | L5: 21.2
A6: 46077 | B6: 0.39583333 | C6: 1號水槽 | D6: P-09 | E6: 202511001 | F6: 21.2 | G6: 21.2 | H6: 23 | I6: 14.03 | J6: =VLOOKUP(D6, [1]設備資料!$A:$E, 5, 0) -> 5 | K6: =IF(I6="", 0, IF(OR(I6=0, AND(J6=2, I6>6.6), AND(J6=3, I6>8.6), AND(J6=5, I6>14.1)), 1, 0)) -> 0 | L6: 21.2
A7: 46077 | B7: 0.39583333 | C7: 1號水槽 | D7: P-10 | E7: 202511002 | F7: 21.2 | G7: 21.2 | H7: 23 | I7: 13.87 | J7: =VLOOKUP(D7, [1]設備資料!$A:$E, 5, 0) -> 5 | K7: =IF(I7="", 0, IF(OR(I7=0, AND(J7=2, I7>6.6), AND(J7=3, I7>8.6), AND(J7=5, I7>14.1)), 1, 0)) -> 0 | L7: 21.2
A8: 46077 | B8: 0.40277778 | C8: 2號水槽 | D8: P-03 | E8: 202510024 | F8: 21.2 | G8: 21.2 | H8: 23 | I8: 6.37 | J8: =VLOOKUP(D8, [1]設備資料!$A:$E, 5, 0) -> 2 | K8: =IF(I8="", 0, IF(OR(I8=0, AND(J8=2, I8>6.6), AND(J8=3, I8>8.6), AND(J8=5, I8>14.1)), 1, 0)) -> 0 | M8: 21
A9: 46077 | B9: 0.40277778 | C9: 2號水槽 | D9: P-04 | E9: 202510026 | F9: 21.2 | H9: 23 | I9: 6.42 | J9: =VLOOKUP(D9, [1]設備資料!$A:$E, 5, 0) -> 2 | K9: =IF(I9="", 0, IF(OR(I9=0, AND(J9=2, I9>6.6), AND(J9=3, I9>8.6), AND(J9=5, I9>14.1)), 1, 0)) -> 0 | M9: 21
A10: 46077 | B10: 0.40277778 | C10: 2號水槽 | D10: P-07 | E10: 202511017 | F10: 21.2 | G10: 21.2 | H10: 23 | I10: 8.24 | J10: =VLOOKUP(D10, [1]設備資料!$A:$E, 5, 0) -> 3 | K10: =IF(I10="", 0, IF(OR(I10=0, AND(J10=2, I10>6.6), AND(J10=3, I10>8.6), AND(J10=5, I10>14.1)), 1, 0)) -> 0 | M10: 21
A11: 46077 | B11: 0.40277778 | C11: 2號水槽 | D11: P-11 | E11: 202511005 | F11: 21.2 | G11: 21.2 | H11: 23 | I11: 14.05 | J11: =VLOOKUP(D11, [1]設備資料!$A:$E, 5, 0) -> 5 | K11: =IF(I11="", 0, IF(OR(I11=0, AND(J11=2, I11>6.6), AND(J11=3, I11>8.6), AND(J11=5, I11>14.1)), 1, 0)) -> 0 | M11: 21
A12: 46077 | B12: 0.40277778 | C12: 2號水槽 | D12: P-12 | E12: NA | F12: 21.2 | G12: 21.2 | H12: 23 | I12: 14.08 | J12: =VLOOKUP(D12, [1]設備資料!$A:$E, 5, 0) -> 5 | K12: =IF(I12="", 0, IF(OR(I12=0, AND(J12=2, I12>6.6), AND(J12=3, I12>8.6), AND(J12=5, I12>14.1)), 1, 0)) -> 0 | M12: 21
A13: 46077 | B13: 0.6875 | C13: 1號水槽 | D13: P-01 | E13: 202510001 | F13: 63.1 | G13: 62.6 | H13: 24 | I13: 6.13 | J13: =VLOOKUP(D13, [1]設備資料!$A:$E, 5, 0) -> 2 | K13: =IF(I13="", 0, IF(OR(I13=0, AND(J13=2, I13>6.6), AND(J13=3, I13>8.6), AND(J13=5, I13>14.1)), 1, 0)) -> 0 | L13: 33.6
A14: 46077 | B14: 0.6875 | C14: 1號水槽 | D14: P-02 | E14: 202510006 | F14: 58.4 | H14: 24 | I14: 6.03 | J14: =VLOOKUP(D14, [1]設備資料!$A:$E, 5, 0) -> 2 | K14: =IF(I14="", 0, IF(OR(I14=0, AND(J14=2, I14>6.6), AND(J14=3, I14>8.6), AND(J14=5, I14>14.1)), 1, 0)) -> 0 | L14: 33.6
A15: 46077 | B15: 0.6875 | C15: 1號水槽 | D15: P-05 | E15: 202511011 | F15: 68.7 | G15: 69.8 | H15: 24 | I15: 8.06 | J15: =VLOOKUP(D15, [1]設備資料!$A:$E, 5, 0) -> 3 | K15: =IF(I15="", 0, IF(OR(I15=0, AND(J15=2, I15>6.6), AND(J15=3, I15>8.6), AND(J15=5, I15>14.1)), 1, 0)) -> 0 | L15: 33.6
A16: 46077 | B16: 0.6875 | C16: 1號水槽 | D16: P-06 | E16: 202511012 | F16: 68.6 | H16: 24 | I16: 7.78 | J16: =VLOOKUP(D16, [1]設備資料!$A:$E, 5, 0) -> 3 | K16: =IF(I16="", 0, IF(OR(I16=0, AND(J16=2, I16>6.6), AND(J16=3, I16>8.6), AND(J16=5, I16>14.1)), 1, 0)) -> 0 | L16: 33.6
A17: 46077 | B17: 0.6875 | C17: 1號水槽 | D17: P-09 | E17: 202511001 | F17: 90.6 | G17: 91.5 | H17: 24 | I17: 13.62 | J17: =VLOOKUP(D17, [1]設備資料!$A:$E, 5, 0) -> 5 | K17: =IF(I17="", 0, IF(OR(I17=0, AND(J17=2, I17>6.6), AND(J17=3, I17>8.6), AND(J17=5, I17>14.1)), 1, 0)) -> 0 | L17: 33.6
A18: 46077 | B18: 0.6875 | C18: 1號水槽 | D18: P-10 | E18: 202511002 | F18: 86.8 | G18: 85.6 | H18: 24 | I18: 13.34 | J18: =VLOOKUP(D18, [1]設備資料!$A:$E, 5, 0) -> 5 | K18: =IF(I18="", 0, IF(OR(I18=0, AND(J18=2, I18>6.6), AND(J18=3, I18>8.6), AND(J18=5, I18>14.1)), 1, 0)) -> 0 | L18: 33.6
A19: 46077 | B19: 0.69444444 | C19: 2號水槽 | D19: P-03 | E19: 202510024 | F19: 62.5 | G19: 62.3 | H19: 24 | I19: 6.17 | J19: =VLOOKUP(D19, [1]設備資料!$A:$E, 5, 0) -> 2 | K19: =IF(I19="", 0, IF(OR(I19=0, AND(J19=2, I19>6.6), AND(J19=3, I19>8.6), AND(J19=5, I19>14.1)), 1, 0)) -> 0 | M19: 33.2
A20: 46077 | B20: 0.69444444 | C20: 2號水槽 | D20: P-04 | E20: 202510026 | F20: 65.8 | H20: 24 | I20: 6.47 | J20: =VLOOKUP(D20, [1]設備資料!$A:$E, 5, 0) -> 2 | K20: =IF(I20="", 0, IF(OR(I20=0, AND(J20=2, I20>6.6), AND(J20=3, I20>8.6), AND(J20=5, I20>14.1)), 1, 0)) -> 0 | M20: 33.2
A21: 46077 | B21: 0.69444444 | C21: 2號水槽 | D21: P-07 | E21: 202511017 | F21: 68.2 | G21: 68.5 | H21: 24 | I21: 7.85 | J21: =VLOOKUP(D21, [1]設備資料!$A:$E, 5, 0) -> 3 | K21: =IF(I21="", 0, IF(OR(I21=0, AND(J21=2, I21>6.6), AND(J21=3, I21>8.6), AND(J21=5, I21>14.1)), 1, 0)) -> 0 | M21: 33.2
A22: 46077 | B22: 0.69444444 | C22: 2號水槽 | D22: P-11 | E22: 202511005 | F22: 90.3 | G22: 89.4 | H22: 24 | I22: 13.35 | J22: =VLOOKUP(D22, [1]設備資料!$A:$E, 5, 0) -> 5 | K22: =IF(I22="", 0, IF(OR(I22=0, AND(J22=2, I22>6.6), AND(J22=3, I22>8.6), AND(J22=5, I22>14.1)), 1, 0)) -> 0 | M22: 33.2
A23: 46077 | B23: 0.69444444 | C23: 2號水槽 | D23: P-12 | E23: NA | F23: 90.4 | G23: 96.1 | H23: 24 | I23: 13.29 | J23: =VLOOKUP(D23, [1]設備資料!$A:$E, 5, 0) -> 5 | K23: =IF(I23="", 0, IF(OR(I23=0, AND(J23=2, I23>6.6), AND(J23=3, I23>8.6), AND(J23=5, I23>14.1)), 1, 0)) -> 0 | M23: 33.2
A24: 46078 | B24: 0.39583333 | C24: 1號水槽 | D24: P-01 | E24: 202510001 | F24: 75.1 | G24: 74.5 | H24: 25 | I24: 6.03 | J24: =VLOOKUP(D24, [1]設備資料!$A:$E, 5, 0) -> 2 | K24: =IF(I24="", 0, IF(OR(I24=0, AND(J24=2, I24>6.6), AND(J24=3, I24>8.6), AND(J24=5, I24>14.1)), 1, 0)) -> 0 | L24: 44.8
A25: 46078 | B25: 0.39583333 | C25: 1號水槽 | D25: P-02 | E25: 202510006 | F25: 71.2 | H25: 25 | I25: 5.78 | J25: =VLOOKUP(D25, [1]設備資料!$A:$E, 5, 0) -> 2 | K25: =IF(I25="", 0, IF(OR(I25=0, AND(J25=2, I25>6.6), AND(J25=3, I25>8.6), AND(J25=5, I25>14.1)), 1, 0)) -> 0 | L25: 44.8
A26: 46078 | B26: 0.39583333 | C26: 1號水槽 | D26: P-05 | E26: 202511011 | F26: 81.1 | G26: 81.9 | H26: 25 | I26: 7.86 | J26: =VLOOKUP(D26, [1]設備資料!$A:$E, 5, 0) -> 3 | K26: =IF(I26="", 0, IF(OR(I26=0, AND(J26=2, I26>6.6), AND(J26=3, I26>8.6), AND(J26=5, I26>14.1)), 1, 0)) -> 0 | L26: 44.8
A27: 46078 | B27: 0.39583333 | C27: 1號水槽 | D27: P-06 | E27: 202511012 | F27: 80.4 | H27: 25 | I27: 7.82 | J27: =VLOOKUP(D27, [1]設備資料!$A:$E, 5, 0) -> 3 | K27: =IF(I27="", 0, IF(OR(I27=0, AND(J27=2, I27>6.6), AND(J27=3, I27>8.6), AND(J27=5, I27>14.1)), 1, 0)) -> 0 | L27: 44.8
A28: 46078 | B28: 0.39583333 | C28: 1號水槽 | D28: P-09 | E28: 202511001 | F28: 102.1 | G28: 102.3 | H28: 25 | I28: 13.64 | J28: =VLOOKUP(D28, [1]設備資料!$A:$E, 5, 0) -> 5 | K28: =IF(I28="", 0, IF(OR(I28=0, AND(J28=2, I28>6.6), AND(J28=3, I28>8.6), AND(J28=5, I28>14.1)), 1, 0)) -> 0 | L28: 44.8
A29: 46078 | B29: 0.39583333 | C29: 1號水槽 | D29: P-10 | E29: 202511002 | F29: 98.2 | G29: 96.5 | H29: 25 | I29: 13.32 | J29: =VLOOKUP(D29, [1]設備資料!$A:$E, 5, 0) -> 5 | K29: =IF(I29="", 0, IF(OR(I29=0, AND(J29=2, I29>6.6), AND(J29=3, I29>8.6), AND(J29=5, I29>14.1)), 1, 0)) -> 0 | L29: 44.8
A30: 46078 | B30: 0.40277778 | C30: 2號水槽 | D30: P-03 | E30: 202510024 | F30: 74.5 | G30: 74.3 | H30: 25 | I30: 6.04 | J30: =VLOOKUP(D30, [1]設備資料!$A:$E, 5, 0) -> 2 | K30: =IF(I30="", 0, IF(OR(I30=0, AND(J30=2, I30>6.6), AND(J30=3, I30>8.6), AND(J30=5, I30>14.1)), 1, 0)) -> 0 | M30: 43.8
A31: 46078 | B31: 0.40277778 | C31: 2號水槽 | D31: P-04 | E31: 202510026 | F31: 77.8 | H31: 25 | I31: 6.08 | J31: =VLOOKUP(D31, [1]設備資料!$A:$E, 5, 0) -> 2 | K31: =IF(I31="", 0, IF(OR(I31=0, AND(J31=2, I31>6.6), AND(J31=3, I31>8.6), AND(J31=5, I31>14.1)), 1, 0)) -> 0 | M31: 43.8
A32: 46078 | B32: 0.40277778 | C32: 2號水槽 | D32: P-07 | E32: 202511017 | F32: 80.2 | G32: 80.9 | H32: 25 | I32: 7.55 | J32: =VLOOKUP(D32, [1]設備資料!$A:$E, 5, 0) -> 3 | K32: =IF(I32="", 0, IF(OR(I32=0, AND(J32=2, I32>6.6), AND(J32=3, I32>8.6), AND(J32=5, I32>14.1)), 1, 0)) -> 0 | M32: 43.8
A33: 46078 | B33: 0.40277778 | C33: 2號水槽 | D33: P-11 | E33: 202511005 | F33: 102.3 | G33: 101.4 | H33: 25 | I33: 13.31 | J33: =VLOOKUP(D33, [1]設備資料!$A:$E, 5, 0) -> 5 | K33: =IF(I33="", 0, IF(OR(I33=0, AND(J33=2, I33>6.6), AND(J33=3, I33>8.6), AND(J33=5, I33>14.1)), 1, 0)) -> 0 | M33: 43.8
A34: 46078 | B34: 0.40277778 | C34: 2號水槽 | D34: P-12 | E34: NA | F34: 102.4 | G34: 97.2 | H34: 25 | I34: 13.23 | J34: =VLOOKUP(D34, [1]設備資料!$A:$E, 5, 0) -> 5 | K34: =IF(I34="", 0, IF(OR(I34=0, AND(J34=2, I34>6.6), AND(J34=3, I34>8.6), AND(J34=5, I34>14.1)), 1, 0)) -> 0 | M34: 43.8
A35: 46078 | B35: 0.6875 | C35: 1號水槽 | D35: P-01 | E35: 202510001 | F35: 75.6 | G35: 74.9 | H35: 27 | J35: =VLOOKUP(D35, [1]設備資料!$A:$E, 5, 0) -> 2 | K35: =IF(I35="", 0, IF(OR(I35=0, AND(J35=2, I35>6.6), AND(J35=3, I35>8.6), AND(J35=5, I35>14.1)), 1, 0)) -> 0 | L35: 45.1
A36: 46078 | B36: 0.6875 | C36: 1號水槽 | D36: P-02 | E36: 202510006 | F36: 71.4 | H36: 27 | J36: =VLOOKUP(D36, [1]設備資料!$A:$E, 5, 0) -> 2 | K36: =IF(I36="", 0, IF(OR(I36=0, AND(J36=2, I36>6.6), AND(J36=3, I36>8.6), AND(J36=5, I36>14.1)), 1, 0)) -> 0 | L36: 45.1
A37: 46078 | B37: 0.6875 | C37: 1號水槽 | D37: P-05 | E37: 202511011 | F37: 81.2 | G37: 82.5 | H37: 27 | J37: =VLOOKUP(D37, [1]設備資料!$A:$E, 5, 0) -> 3 | K37: =IF(I37="", 0, IF(OR(I37=0, AND(J37=2, I37>6.6), AND(J37=3, I37>8.6), AND(J37=5, I37>14.1)), 1, 0)) -> 0 | L37: 45.1
A38: 46078 | B38: 0.6875 | C38: 1號水槽 | D38: P-06 | E38: 202511012 | F38: 80.9 | H38: 27 | J38: =VLOOKUP(D38, [1]設備資料!$A:$E, 5, 0) -> 3 | K38: =IF(I38="", 0, IF(OR(I38=0, AND(J38=2, I38>6.6), AND(J38=3, I38>8.6), AND(J38=5, I38>14.1)), 1, 0)) -> 0 | L38: 45.1
A39: 46078 | B39: 0.6875 | C39: 1號水槽 | D39: P-09 | E39: 202511001 | F39: 103.1 | G39: 101.8 | H39: 27 | J39: =VLOOKUP(D39, [1]設備資料!$A:$E, 5, 0) -> 5 | K39: =IF(I39="", 0, IF(OR(I39=0, AND(J39=2, I39>6.6), AND(J39=3, I39>8.6), AND(J39=5, I39>14.1)), 1, 0)) -> 0 | L39: 45.1
A40: 46078 | B40: 0.6875 | C40: 1號水槽 | D40: P-10 | E40: 202511002 | F40: 98 | G40: 97.2 | H40: 27 | J40: =VLOOKUP(D40, [1]設備資料!$A:$E, 5, 0) -> 5 | K40: =IF(I40="", 0, IF(OR(I40=0, AND(J40=2, I40>6.6), AND(J40=3, I40>8.6), AND(J40=5, I40>14.1)), 1, 0)) -> 0 | L40: 45.1
...
